Workbook
Name Slicer_Diabetes_Status: #N/A
Name Slicer_Weight_Status: #N/A

Sheet Customer Names
A1: Customer ID | B1: name | C1: Title | D1: First Name | E1: Last Name
A2: Id1 | B2: Hawks, Ms. Kelly | C2: =MID(B2, FIND(", ",B2)+2, FIND(".",B2)-FIND(", ", B2)-2) -> Ms | D2: =TRIM(RIGHT(B2, LEN(B2) - FIND(".", B2))) -> Kelly | E2: =LEFT(B2, FIND(",", B2)-1) -> Hawks
A3: Id2 | B3: Lehner, Mr. Matthew D | C3: =MID(B3, FIND(", ",B3)+2, FIND(".",B3)-FIND(", ", B3)-2) -> Mr | D3: =TRIM(RIGHT(B3, LEN(B3) - FIND(".", B3))) -> Matthew D | E3: =LEFT(B3, FIND(",", B3)-1) -> Lehner
A4: Id3 | B4: Lu, Mr. Phil | C4: =MID(B4, FIND(", ",B4)+2, FIND(".",B4)-FIND(", ", B4)-2) -> Mr | D4: =TRIM(RIGHT(B4, LEN(B4) - FIND(".", B4))) -> Phil | E4: =LEFT(B4, FIND(",", B4)-1) -> Lu
A5: Id4 | B5: Osborne, Ms. Kelsey | C5: =MID(B5, FIND(", ",B5)+2, FIND(".",B5)-FIND(", ", B5)-2) -> Ms | D5: =TRIM(RIGHT(B5, LEN(B5) - FIND(".", B5))) -> Kelsey | E5: =LEFT(B5, FIND(",", B5)-1) -> Osborne
A6: Id5 | B6: Kadala, Ms. Kristyn | C6: =MID(B6, FIND(", ",B6)+2, FIND(".",B6)-FIND(", ", B6)-2) -> Ms | D6: =TRIM(RIGHT(B6, LEN(B6) - FIND(".", B6))) -> Kristyn | E6: =LEFT(B6, FIND(",", B6)-1) -> Kadala
A7: Id6 | B7: Baker, Mr. Russell B. | C7: =MID(B7, FIND(", ",B7)+2, FIND(".",B7)-FIND(", ", B7)-2) -> Mr | D7: =TRIM(RIGHT(B7, LEN(B7) - FIND(".", B7))) -> Russell B. | E7: =LEFT(B7, FIND(",", B7)-1) -> Baker
A8: Id7 | B8: Macpherson, Mr. Scott | C8: =MID(B8, FIND(", ",B8)+2, FIND(".",B8)-FIND(", ", B8)-2) -> Mr | D8: =TRIM(RIGHT(B8, LEN(B8) - FIND(".", B8))) -> Scott | E8: =LEFT(B8, FIND(",", B8)-1) -> Macpherson
A9: Id8 | B9: Hallman, Mr. Stephen | C9: =MID(B9, FIND(", ",B9)+2, FIND(".",B9)-FIND(", ", B9)-2) -> Mr | D9: =TRIM(RIGHT(B9, LEN(B9) - FIND(".", B9))) -> Stephen | E9: =LEFT(B9, FIND(",", B9)-1) -> Hallman
A10: Id9 | B10: Moran, Mr. Patrick R. | C10: =MID(B10, FIND(", ",B10)+2, FIND(".",B10)-FIND(", ", B10)-2) -> Mr | D10: =TRIM(RIGHT(B10, LEN(B10) - FIND(".", B10))) -> Patrick R. | E10: =LEFT(B10, FIND(",", B10)-1) -> Moran
A11: Id10 | B11: Benner, Ms. Brooke N. | C11: =MID(B11, FIND(", ",B11)+2, FIND(".",B11)-FIND(", ", B11)-2) -> Ms | D11: =TRIM(RIGHT(B11, LEN(B11) - FIND(".", B11))) -> Brooke N. | E11: =LEFT(B11, FIND(",", B11)-1) -> Benner
A12: Id11 | B12: Fierro Vargas, Ms. Paola Andrea | C12: =MID(B12, FIND(", ",B12)+2, FIND(".",B12)-FIND(", ", B12)-2) -> Ms | D12: =TRIM(RIGHT(B12, LEN(B12) - FIND(".", B12))) -> Paola Andrea | E12: =LEFT(B12, FIND(",", B12)-1) -> Fierro Vargas
A13: Id12 | B13: Franz, Mr. David | C13: =MID(B13, FIND(", ",B13)+2, FIND(".",B13)-FIND(", ", B13)-2) -> Mr | D13: =TRIM(RIGHT(B13, LEN(B13) - FIND(".", B13))) -> David | E13: =LEFT(B13, FIND(",", B13)-1) -> Franz
... A2336: Id2335 | B2336: German, Mr. Aaron K | C2336: =MID(B2336, FIND(", ",B2336)+2, FIND(".",B2336)-FIND(", ", B2336)-2) -> Mr | D2336: =TRIM(RIGHT(B2336, LEN(B2336) - FIND(".", B2336))) -> Aaron K | E2336: =LEFT(B2336, FIND(",", B2336)-1) -> German

Sheet Medical Examinations
A1: Customer ID | B1: BMI | C1: Weight Status | D1: HBA1C | E1: Diabetes Status | F1: Heart Issues | G1: Any Transplants | H1: Cancer history | I1: NumberOfMajorSurgeries | J1: Number of Major Surgeries Converted | K1: smoker | L1: smoker modified
A2: Id1 | B2: 47.41 | C2: =IF(B2<18.5,"Underweight",IF(B2<24.99,"Normal Weight",IF(B2<29.99,"Overweight","Obesity"))) -> Obesity | D2: 7.47 | E2: =IF(D2<5.7,"Normal",IF(D2<6.5,"Prediabeties","Diabetes")) -> Diabetes | F2: No | G2: No | H2: No | I2: No major surgery | J2: =IF(I2="No major surgery", 0, I2) -> 0 | K2: yes | L2: =IF(K2="?", "No", K2) -> yes | M2: =COUNTIF(K:K, "yes") -> 488 | N2: Smokers
A3: Id2 | B3: 30.36 | C3: =IF(B3<18.5,"Underweight",IF(B3<24.99,"Normal Weight",IF(B3<29.99,"Overweight","Obesity"))) -> Obesity | D3: 5.77 | E3: =IF(D3<5.7,"Normal",IF(D3<6.5,"Prediabeties","Diabetes")) -> Prediabeties | F3: No | G3: No | H3: No | I3: No major surgery | J3: =IF(I3="No major surgery", 0, I3) -> 0 | K3: yes | L3: =IF(K3="?", "No", K3) -> yes | M3: =COUNTIF(K:K, "no") -> 1845 | N3: Non-Smokers
A4: Id3 | B4: 34.485 | C4: =IF(B4<18.5,"Underweight",IF(B4<24.99,"Normal Weight",IF(B4<29.99,"Overweight","Obesity"))) -> Obesity | D4: 11.87 | E4: =IF(D4<5.7,"Normal",IF(D4<6.5,"Prediabeties","Diabetes")) -> Diabetes | F4: yes | G4: No | H4: No | I4: 2 | J4: =IF(I4="No major surgery", 0, I4) -> 2 | K4: yes | L4: =IF(K4="?", "No", K4) -> yes
A5: Id4 | B5: 38.095 | C5: =IF(B5<18.5,"Underweight",IF(B5<24.99,"Normal Weight",IF(B5<29.99,"Overweight","Obesity"))) -> Obesity | D5: 6.05 | E5: =IF(D5<5.7,"Normal",IF(D5<6.5,"Prediabeties","Diabetes")) -> Prediabeties | F5: No | G5: No | H5: No | I5: No major surgery | J5: =IF(I5="No major surgery", 0, I5) -> 0 | K5: yes | L5: =IF(K5="?", "No", K5) -> yes
A6: Id5 | B6: 35.53 | C6: =IF(B6<18.5,"Underweight",IF(B6<24.99,"Normal Weight",IF(B6<29.99,"Overweight","Obesity"))) -> Obesity | D6: 5.45 | E6: =IF(D6<5.7,"Normal",IF(D6<6.5,"Prediabeties","Diabetes")) -> Normal | F6: No | G6: No | H6: No | I6: No major surgery | J6: =IF(I6="No major surgery", 0, I6) -> 0 | K6: yes | L6: =IF(K6="?", "No", K6) -> yes
A7: Id6 | B7: 32.8 | C7: =IF(B7<18.5,"Underweight",IF(B7<24.99,"Normal Weight",IF(B7<29.99,"Overweight","Obesity"))) -> Obesity | D7: 6.59 | E7: =IF(D7<5.7,"Normal",IF(D7<6.5,"Prediabeties","Diabetes")) -> Diabetes | F7: No | G7: No | H7: No | I7: No major surgery | J7: =IF(I7="No major surgery", 0, I7) -> 0 | K7: yes | L7: =IF(K7="?", "No", K7) -> yes
A8: Id7 | B8: 36.4 | C8: =IF(B8<18.5,"Underweight",IF(B8<24.99,"Normal Weight",IF(B8<29.99,"Overweight","Obesity"))) -> Obesity | D8: 6.07 | E8: =IF(D8<5.7,"Normal",IF(D8<6.5,"Prediabeties","Diabetes")) -> Prediabeties | F8: No | G8: No | H8: No | I8: No major surgery | J8: =IF(I8="No major surgery", 0, I8) -> 0 | K8: yes | L8: =IF(K8="?", "No", K8) -> yes
A9: Id8 | B9: 36.96 | C9: =IF(B9<18.5,"Underweight",IF(B9<24.99,"Normal Weight",IF(B9<29.99,"Overweight","Obesity"))) -> Obesity | D9: 7.93 | E9: =IF(D9<5.7,"Normal",IF(D9<6.5,"Prediabeties","Diabetes")) -> Diabetes | F9: No | G9: No | H9: No | I9: 3 | J9: =IF(I9="No major surgery", 0, I9) -> 3 | K9: yes | L9: =IF(K9="?", "No", K9) -> yes
A10: Id9 | B10: 41.14 | C10: =IF(B10<18.5,"Underweight",IF(B10<24.99,"Normal Weight",IF(B10<29.99,"Overweight","Obesity"))) -> Obesity | D10: 9.58 | E10: =IF(D10<5.7,"Normal",IF(D10<6.5,"Prediabeties","Diabetes")) -> Diabetes | F10: yes | G10: No | H10: Yes | I10: 1 | J10: =IF(I10="No major surgery", 0, I10) -> 1 | K10: yes | L10: =IF(K10="?", "No", K10) -> yes
A11: Id10 | B11: 38.06 | C11: =IF(B11<18.5,"Underweight",IF(B11<24.99,"Normal Weight",IF(B11<29.99,"Overweight","Obesity"))) -> Obesity | D11: 10.79 | E11: =IF(D11<5.7,"Normal",IF(D11<6.5,"Prediabeties","Diabetes")) -> Diabetes | F11: No | G11: No | H11: No | I11: No major surgery | J11: =IF(I11="No major surgery", 0, I11) -> 0 | K11: yes | L11: =IF(K11="?", "No", K11) -> yes
A12: Id11 | B12: 37.7 | C12: =IF(B12<18.5,"Underweight",IF(B12<24.99,"Normal Weight",IF(B12<29.99,"Overweight","Obesity"))) -> Obesity | D12: 5.96 | E12: =IF(D12<5.7,"Normal",IF(D12<6.5,"Prediabeties","Diabetes")) -> Prediabeties | F12: yes | G12: No | H12: No | I12: 2 | J12: =IF(I12="No major surgery", 0, I12) -> 2 | K12: yes | L12: =IF(K12="?", "No", K12) -> yes
A13: Id12 | B13: 42.13 | C13: =IF(B13<18.5,"Underweight",IF(B13<24.99,"Normal Weight",IF(B13<29.99,"Overweight","Obesity"))) -> Obesity | D13: 11.9 | E13: =IF(D13<5.7,"Normal",IF(D13<6.5,"Prediabeties","Diabetes")) -> Diabetes | F13: No | G13: No | H13: No | I13: No major surgery | J13: =IF(I13="No major surgery", 0, I13) -> 0 | K13: yes | L13: =IF(K13="?", "No", K13) -> yes
A14: Id13 | B14: 40.92 | C14: =IF(B14<18.5,"Underweight",IF(B14<24.99,"Normal Weight",IF(B14<29.99,"Overweight","Obesity"))) -> Obesity | D14: 8.41 | E14: =IF(D14<5.7,"Normal",IF(D14<6.5,"Prediabeties","Diabetes")) -> Diabetes | F14: No | G14: No | H14: No | I14: No major surgery | J14: =IF(I14="No major surgery", 0, I14) -> 0 | K14: yes | L14: =IF(K14="?", "No", K14) -> yes
A15: Id14 | B15: 40.565 | C15: =IF(B15<18.5,"Underweight",IF(B15<24.99,"Normal Weight",IF(B15<29.99,"Overweight","Obesity"))) -> Obesity | D15: 7.02 | E15: =IF(D15<5.7,"Normal",IF(D15<6.5,"Prediabeties","Diabetes")) -> Diabetes | F15: No | G15: No | H15: No | I15: No major surgery | J15: =IF(I15="No major surgery", 0, I15) -> 0 | K15: yes | L15: =IF(K15="?", "No", K15) -> yes
A16: Id15 | B16: 36.385 | C16: =IF(B16<18.5,"Underweight",IF(B16<24.99,"Normal Weight",IF(B16<29.99,"Overweight","Obesity"))) -> Obesity | D16: 7.59 | E16: =IF(D16<5.7,"Normal",IF(D16<6.5,"Prediabeties","Diabetes")) -> Diabetes | F16: yes | G16: No | H16: No | I16: 2 | J16: =IF(I16="No major surgery", 0, I16) -> 2 | K16: yes | L16: =IF(K16="?", "No", K16) -> yes
A17: Id16 | B17: 39.9 | C17: =IF(B17<18.5,"Underweight",IF(B17<24.99,"Normal Weight",IF(B17<29.99,"Overweight","Obesity"))) -> Obesity | D17: 11.32 | E17: =IF(D17<5.7,"Normal",IF(D17<6.5,"Prediabeties","Diabetes")) -> Diabetes | F17: No | G17: No | H17: No | I17: No major surgery | J17: =IF(I17="No major surgery", 0, I17) -> 0 | K17: yes | L17: =IF(K17="?", "No", K17) -> yes
A18: Id17 | B18: 33.8 | C18: =IF(B18<18.5,"Underweight",IF(B18<24.99,"Normal Weight",IF(B18<29.99,"Overweight","Obesity"))) -> Obesity | D18: 7.67 | E18: =IF(D18<5.7,"Normal",IF(D18<6.5,"Prediabeties","Diabetes")) -> Diabetes | F18: No | G18: No | H18: No | I18: 3 | J18: =IF(I18="No major surgery", 0, I18) -> 3 | K18: yes | L18: =IF(K18="?", "No", K18) -> yes
A19: Id18 | B19: 36.765 | C19: =IF(B19<18.5,"Underweight",IF(B19<24.99,"Normal Weight",IF(B19<29.99,"Overweight","Obesity"))) -> Obesity | D19: 7.29 | E19: =IF(D19<5.7,"Normal",IF(D19<6.5,"Prediabeties","Diabetes")) -> Diabetes | F19: yes | G19: No | H19: Yes | I19: 1 | J19: =IF(I19="No major surgery", 0, I19) -> 1 | K19: yes | L19: =IF(K19="?", "No", K19) -> yes
A20: Id19 | B20: 36.955 | C20: =IF(B20<18.5,"Underweight",IF(B20<24.99,"Normal Weight",IF(B20<29.99,"Overweight","Obesity"))) -> Obesity | D20: 4.72 | E20: =IF(D20<5.7,"Normal",IF(D20<6.5,"Prediabeties","Diabetes")) -> Normal | F20: yes | G20: No | H20: No | I20: 1 | J20: =IF(I20="No major surgery", 0, I20) -> 1 | K20: yes | L20: =IF(K20="?", "No", K20) -> yes
A21: Id20 | B21: 42.9 | C21: =IF(B21<18.5,"Underweight",IF(B21<24.99,"Normal Weight",IF(B21<29.99,"Overweight","Obesity"))) -> Obesity | D21: 11.41 | E21: =IF(D21<5.7,"Normal",IF(D21<6.5,"Prediabeties","Diabetes")) -> Diabetes | F21: No | G21: No | H21: No | I21: No major surgery | J21: =IF(I21="No major surgery", 0, I21) -> 0 | K21: yes | L21: =IF(K21="?", "No", K21) -> yes
A22: Id21 | B22: 36.3 | C22: =IF(B22<18.5,"Underweight",IF(B22<24.99,"Normal Weight",IF(B22<29.99,"Overweight","Obesity"))) -> Obesity | D22: 11.5 | E22: =IF(D22<5.7,"Normal",IF(D22<6.5,"Prediabeties","Diabetes")) -> Diabetes | F22: yes | G22: No | H22: No | I22: 2 | J22: =IF(I22="No major surgery", 0, I22) -> 2 | K22: yes | L22: =IF(K22="?", "No", K22) -> yes
A23: Id22 | B23: 32.2 | C23: =IF(B23<18.5,"Underweight",IF(B23<24.99,"Normal Weight",IF(B23<29.99,"Overweight","Obesity"))) -> Obesity | D23: 6.22 | E23: =IF(D23<5.7,"Normal",IF(D23<6.5,"Prediabeties","Diabetes")) -> Prediabeties | F23: yes | G23: No | H23: No | I23: 2 | J23: =IF(I23="No major surgery", 0, I23) -> 2 | K23: yes | L23: =IF(K23="?", "No", K23) -> yes
A24: Id23 | B24: 31.3 | C24: =IF(B24<18.5,"Underweight",IF(B24<24.99,"Normal Weight",IF(B24<29.99,"Overweight","Obesity"))) -> Obesity | D24: 11.38 | E24: =IF(D24<5.7,"Normal",IF(D24<6.5,"Prediabeties","Diabetes")) -> Diabetes | F24: No | G24: No | H24: No | I24: 3 | J24: =IF(I24="No major surgery", 0, I24) -> 3 | K24: yes | L24: =IF(K24="?", "No", K24) -> yes
A25: Id24 | B25: 41.8 | C25: =IF(B25<18.5,"Underweight",IF(B25<24.99,"Normal Weight",IF(B25<29.99,"Overweight","Obesity"))) -> Obesity | D25: 7.89 | E25: =IF(D25<5.7,"Normal",IF(D25<6.5,"Prediabeties","Diabetes")) -> Diabetes | F25: yes | G25: No | H25: No | I25: 2 | J25: =IF(I25="No major surgery", 0, I25) -> 2 | K25: yes | L25: =IF(K25="?", "No", K25) -> yes
A26: Id25 | B26: 35.09 | C26: =IF(B26<18.5,"Underweight",IF(B26<24.99,"Normal Weight",IF(B26<29.99,"Overweight","Obesity"))) -> Obesity | D26: 4.38 | E26: =IF(D26<5.7,"Normal",IF(D26<6.5,"Prediabeties","Diabetes")) -> Normal | F26: yes | G26: No | H26: No | I26: 2 | J26: =IF(I26="No major surgery", 0, I26) -> 2 | K26: yes | L26: =IF(K26="?", "No", K26) -> yes
A27: Id26 | B27: 33.88 | C27: =IF(B27<18.5,"Underweight",IF(B27<24.99,"Normal Weight",IF(B27<29.99,"Overweight","Obesity"))) -> Obesity | D27: 7.01 | E27: =IF(D27<5.7,"Normal",IF(D27<6.5,"Prediabeties","Diabetes")) -> Diabetes | F27: No | G27: No | H27: No | I27: 3 | J27: =IF(I27="No major surgery", 0, I27) -> 3 | K27: yes | L27: =IF(K27="?", "No", K27) -> yes
A28: Id27 | B28: 30.875 | C28: =IF(B28<18.5,"Underweight",IF(B28<24.99,"Normal Weight",IF(B28<29.99,"Overweight","Obesity"))) -> Obesity | D28: 11.88 | E28: =IF(D28<5.7,"Normal",IF(D28<6.5,"Prediabeties","Diabetes")) -> Diabetes | F28: No | G28: No | H28: No | I28: No major surgery | J28: =IF(I28="No major surgery", 0, I28) -> 0 | K28: yes | L28: =IF(K28="?", "No", K28) -> yes
A29: Id28 | B29: 36.86 | C29: =IF(B29<18.5,"Underweight",IF(B29<24.99,"Normal Weight",IF(B29<29.99,"Overweight","Obesity"))) -> Obesity | D29: 5.19 | E29: =IF(D29<5.7,"Normal",IF(D29<6.5,"Prediabeties","Diabetes")) -> Normal | F29: yes | G29: No | H29: Yes | I29: 1 | J29: =IF(I29="No major surgery", 0, I29) -> 1 | K29: yes | L29: =IF(K29="?", "No", K29) -> yes
A30: Id29 | B30: 35.86 | C30: =IF(B30<18.5,"Underweight",IF(B30<24.99,"Normal Weight",IF(B30<29.99,"Overweight","Obesity"))) -> Obesity | D30: 6.74 | E30: =IF(D30<5.7,"Normal",IF(D30<6.5,"Prediabeties","Diabetes")) -> Diabetes | F30: yes | G30: No | H30: No | I30: 2 | J30: =IF(I30="No major surgery", 0, I30) -> 2 | K30: yes | L30: =IF(K30="?", "No", K30) -> yes
A31: Id30 | B31: 37.05 | C31: =IF(B31<18.5,"Underweight",IF(B31<24.99,"Normal Weight",IF(B31<29.99,"Overweight","Obesity"))) -> Obesity | D31: 8.44 | E31: =IF(D31<5.7,"Normal",IF(D31<6.5,"Prediabeties","Diabetes")) -> Diabetes | F31: No | G31: No | H31: No | I31: No major surgery | J31: =IF(I31="No major surgery", 0, I31) -> 0 | K31: yes | L31: =IF(K31="?", "No", K31) -> yes
A32: Id31 | B32: 43.89 | C32: =IF(B32<18.5,"Underweight",IF(B32<24.99,"Normal Weight",IF(B32<29.99,"Overweight","Obesity"))) -> Obesity | D32: 8.71 | E32: =IF(D32<5.7,"Normal",IF(D32<6.5,"Prediabeties","Diabetes")) -> Diabetes | F32: No | G32: No | H32: No | I32: No major surgery | J32: =IF(I32="No major surgery", 0, I32) -> 0 | K32: yes | L32: =IF(K32="?", "No", K32) -> yes
A33: Id32 | B33: 42.35 | C33: =IF(B33<18.5,"Underweight",IF(B33<24.99,"Normal Weight",IF(B33<29.99,"Overweight","Obesity"))) -> Obesity | D33: 5.08 | E33: =IF(D33<5.7,"Normal",IF(D33<6.5,"Prediabeties","Diabetes")) -> Normal | F33: yes | G33: No | H33: No | I33: No major surgery | J33: =IF(I33="No major surgery", 0, I33) -> 0 | K33: yes | L33: =IF(K33="?", "No", K33) -> yes
A34: Id33 | B34: 31.35 | C34: =IF(B34<18.5,"Underweight",IF(B34<24.99,"Normal Weight",IF(B34<29.99,"Overweight","Obesity"))) -> Obesity | D34: 6.86 | E34: =IF(D34<5.7,"Normal",IF(D34<6.5,"Prediabeties","Diabetes")) -> Diabetes | F34: No | G34: No | H34: No | I34: No major surgery | J34: =IF(I34="No major surgery", 0, I34) -> 0 | K34: yes | L34: =IF(K34="?", "No", K34) -> yes
A35: Id34 | B35: 47.6 | C35: =IF(B35<18.5,"Underweight",IF(B35<24.99,"Normal Weight",IF(B35<29.99,"Overweight","Obesity"))) -> Obesity | D35: 5.95 | E35: =IF(D35<5.7,"Normal",IF(D35<6.5,"Prediabeties","Diabetes")) -> Prediabeties | F35: yes | G35: No | H35: No | I35: No major surgery | J35: =IF(I35="No major surgery", 0, I35) -> 0 | K35: yes | L35: =IF(K35="?", "No", K35) -> yes
A36: Id35 | B36: 46.2 | C36: =IF(B36<18.5,"Underweight",IF(B36<24.99,"Normal Weight",IF(B36<29.99,"Overweight","Obesity"))) -> Obesity | D36: 6.09 | E36: =IF(D36<5.7,"Normal",IF(D36<6.5,"Prediabeties","Diabetes")) -> Prediabeties | F36: No | G36: No | H36: Yes | I36: 1 | J36: =IF(I36="No major surgery", 0, I36) -> 1 | K36: yes | L36: =IF(K36="?", "No", K36) -> yes
A37: Id36 | B37: 32.015 | C37: =IF(B37<18.5,"Underweight",IF(B37<24.99,"Normal Weight",IF(B37<29.99,"Overweight","Obesity"))) -> Obesity | D37: 11.75 | E37: =IF(D37<5.7,"Normal",IF(D37<6.5,"Prediabeties","Diabetes")) -> Diabetes | F37: No | G37: No | H37: No | I37: No major surgery | J37: =IF(I37="No major surgery", 0, I37) -> 0 | K37: yes | L37: =IF(K37="?", "No", K37) -> yes
A38: Id37 | B38: 40.565 | C38: =IF(B38<18.5,"Underweight",IF(B38<24.99,"Normal Weight",IF(B38<29.99,"Overweight","Obesity"))) -> Obesity | D38: 7.37 | E38: =IF(D38<5.7,"Normal",IF(D38<6.5,"Prediabeties","Diabetes")) -> Diabetes | F38: No | G38: No | H38: No | I38: No major surgery | J38: =IF(I38="No major surgery", 0, I38) -> 0 | K38: yes | L38: =IF(K38="?", "No", K38) -> yes
A39: Id38 | B39: 32.45 | C39: =IF(B39<18.5,"Underweight",IF(B39<24.99,"Normal Weight",IF(B39<29.99,"Overweight","Obesity"))) -> Obesity | D39: 11.91 | E39: =IF(D39<5.7,"Normal",IF(D39<6.5,"Prediabeties","Diabetes")) -> Diabetes | F39: No | G39: No | H39: No | I39: No major surgery | J39: =IF(I39="No major surgery", 0, I39) -> 0 | K39: yes | L39: =IF(K39="?", "No", K39) -> yes
A40: Id39 | B40: 34.96 | C40: =IF(B40<18.5,"Underweight",IF(B40<24.99,"Normal Weight",IF(B40<29.99,"Overweight","Obesity"))) -> Obesity | D40: 6.52 | E40: =IF(D40<5.7,"Normal",IF(D40<6.5,"Prediabeties","Diabetes")) -> Diabetes | F40: No | G40: No | H40: No | I40: No major surgery | J40: =IF(I40="No major surgery", 0, I40) -> 0 | K40: yes | L40: =IF(K40="?", "No", K40) -> yes
...

Sheet Hospitalisation Details
A1: Customer ID | B1: year | C1: year modified | D1: month | E1: Month modified | F1: date | G1: Date of Birth | H1: Age | I1: children | J1: charges | K1: Hospital tier | L1: Hospital tier modified | M1: City tier | N1: City tier modified | O1: State ID | P1: State ID modified
A2: Id2335 | B2: 1992 | C2: =IF(B2="?", ROUND(AVERAGEIF(B:B, "<>?"), 0), B2) -> 1992 | D2: Jul | E2: =IF(D2="?", "Sep", D2) -> Jul | F2: 9 | G2: =DATE(C2, MONTH(1&E2), F2) -> 33794 | H2: =DATEDIF(G2, DATE(2023,6,8), "Y") -> 30 | I2: 0 | J2: 563.84 | K2: tier - 2 | L2: =IF(K2="?", "tier - 1", K2) -> tier - 2 | M2: tier - 3 | N2: =IF(M2="?", "tier - 2", M2) -> tier - 3 | O2: R1013 | P2: =IF(O2="?", "Unknown", O2) -> R1013 | R2: Hospital Tier - Most Frequent
A3: Id2334 | B3: 1992 | C3: =IF(B3="?", ROUND(AVERAGEIF(B:B, "<>?"), 0), B3) -> 1992 | D3: Nov | E3: =IF(D3="?", "Sep", D3) -> Nov | F3: 30 | G3: =DATE(C3, MONTH(1&E3), F3) -> 33938 | H3: =DATEDIF(G3, DATE(2023,6,8), "Y") -> 30 | I3: 0 | J3: 570.62 | K3: tier - 2 | L3: =IF(K3="?", "tier - 1", K3) -> tier - 2 | M3: tier - 1 | N3: =IF(M3="?", "tier - 2", M3) -> tier - 1 | O3: R1013 | P3: =IF(O3="?", "Unknown", O3) -> R1013 | R3: Tier 1 | S3: =COUNTIF(K:K, "tier - 2") -> 1338
A4: Id2333 | B4: 1993 | C4: =IF(B4="?", ROUND(AVERAGEIF(B:B, "<>?"), 0), B4) -> 1993 | D4: Jun | E4: =IF(D4="?", "Sep", D4) -> Jun | F4: 30 | G4: =DATE(C4, MONTH(1&E4), F4) -> 34150 | H4: =DATEDIF(G4, DATE(2023,6,8), "Y") -> 29 | I4: 0 | J4: 600 | K4: tier - 2 | L4: =IF(K4="?", "tier - 1", K4) -> tier - 2 | M4: tier - 1 | N4: =IF(M4="?", "tier - 2", M4) -> tier - 1 | O4: R1013 | P4: =IF(O4="?", "Unknown", O4) -> R1013 | R4: Tier2 | S4: =COUNTIF(K:K, "tier - 1") -> 305
A5: Id2332 | B5: 1992 | C5: =IF(B5="?", ROUND(AVERAGEIF(B:B, "<>?"), 0), B5) -> 1992 | D5: Sep | E5: =IF(D5="?", "Sep", D5) -> Sep | F5: 13 | G5: =DATE(C5, MONTH(1&E5), F5) -> 33860 | H5: =DATEDIF(G5, DATE(2023,6,8), "Y") -> 30 | I5: 0 | J5: 604.54 | K5: tier - 3 | L5: =IF(K5="?", "tier - 1", K5) -> tier - 3 | M5: tier - 3 | N5: =IF(M5="?", "tier - 2", M5) -> tier - 3 | O5: R1013 | P5: =IF(O5="?", "Unknown", O5) -> R1013 | R5: Tier 3 | S5: =COUNTIF(K:K, "tier - 3") -> 693
A6: Id2331 | B6: 1998 | C6: =IF(B6="?", ROUND(AVERAGEIF(B:B, "<>?"), 0), B6) -> 1998 | D6: Jul | E6: =IF(D6="?", "Sep", D6) -> Jul | F6: 27 | G6: =DATE(C6, MONTH(1&E6), F6) -> 36003 | H6: =DATEDIF(G6, DATE(2023,6,8), "Y") -> 24 | I6: 0 | J6: 637.26 | K6: tier - 3 | L6: =IF(K6="?", "tier - 1", K6) -> tier - 3 | M6: tier - 3 | N6: =IF(M6="?", "tier - 2", M6) -> tier - 3 | O6: R1013 | P6: =IF(O6="?", "Unknown", O6) -> R1013
A7: Id2330 | B7: 2001 | C7: =IF(B7="?", ROUND(AVERAGEIF(B:B, "<>?"), 0), B7) -> 2001 | D7: Nov | E7: =IF(D7="?", "Sep", D7) -> Nov | F7: 20 | G7: =DATE(C7, MONTH(1&E7), F7) -> 37215 | H7: =DATEDIF(G7, DATE(2023,6,8), "Y") -> 21 | I7: 0 | J7: 646.14 | K7: tier - 3 | L7: =IF(K7="?", "tier - 1", K7) -> tier - 3 | M7: tier - 3 | N7: =IF(M7="?", "tier - 2", M7) -> tier - 3 | O7: R1012 | P7: =IF(O7="?", "Unknown", O7) -> R1012 | R7: City Tier - Most frequent
A8: Id2329 | B8: 1993 | C8: =IF(B8="?", ROUND(AVERAGEIF(B:B, "<>?"), 0), B8) -> 1993 | D8: Jun | E8: =IF(D8="?", "Sep", D8) -> Jun | F8: 1 | G8: =DATE(C8, MONTH(1&E8), F8) -> 34121 | H8: =DATEDIF(G8, DATE(2023,6,8), "Y") -> 30 | I8: 0 | J8: 650 | K8: tier - 3 | L8: =IF(K8="?", "tier - 1", K8) -> tier - 3 | M8: tier - 3 | N8: =IF(M8="?", "tier - 2", M8) -> tier - 3 | O8: R1013 | P8: =IF(O8="?", "Unknown", O8) -> R1013 | R8: Tier 1 | S8: =COUNTIF(M:M, "tier - 1") -> 732
A9: Id2328 | B9: 1995 | C9: =IF(B9="?", ROUND(AVERAGEIF(B:B, "<>?"), 0), B9) -> 1995 | D9: Jul | E9: =IF(D9="?", "Sep", D9) -> Jul | F9: 4 | G9: =DATE(C9, MONTH(1&E9), F9) -> 34884 | H9: =DATEDIF(G9, DATE(2023,6,8), "Y") -> 27 | I9: 0 | J9: 650 | K9: tier - 3 | L9: =IF(K9="?", "tier - 1", K9) -> tier - 3 | M9: tier - 3 | N9: =IF(M9="?", "tier - 2", M9) -> tier - 3 | O9: R1013 | P9: =IF(O9="?", "Unknown", O9) -> R1013 | R9: Tier2 | S9: =COUNTIF(M:M, "tier - 2") -> 809
A10: Id2327 | B10: 2002 | C10: =IF(B10="?", ROUND(AVERAGEIF(B:B, "<>?"), 0), B10) -> 2002 | D10: Nov | E10: =IF(D10="?", "Sep", D10) -> Nov | F10: 29 | G10: =DATE(C10, MONTH(1&E10), F10) -> 37589 | H10: =DATEDIF(G10, DATE(2023,6,8), "Y") -> 20 | I10: 0 | J10: 668 | K10: tier - 3 | L10: =IF(K10="?", "tier - 1", K10) -> tier - 3 | M10: tier - 2 | N10: =IF(M10="?", "tier - 2", M10) -> tier - 2 | O10: R1012 | P10: =IF(O10="?", "Unknown", O10) -> R1012 | R10: Tier 3 | S10: =COUNTIF(M:M, "tier - 3") -> 795
A11: Id2326 | B11: 1997 | C11: =IF(B11="?", ROUND(AVERAGEIF(B:B, "<>?"), 0), B11) -> 1997 | D11: Nov | E11: =IF(D11="?", "Sep", D11) -> Nov | F11: 9 | G11: =DATE(C11, MONTH(1&E11), F11) -> 35743 | H11: =DATEDIF(G11, DATE(2023,6,8), "Y") -> 25 | I11: 0 | J11: 670 | K11: tier - 3 | L11: =IF(K11="?", "tier - 1", K11) -> tier - 3 | M11: tier - 3 | N11: =IF(M11="?", "tier - 2", M11) -> tier - 3 | O11: R1013 | P11: =IF(O11="?", "Unknown", O11) -> R1013
A12: Id2325 | B12: 2001 | C12: =IF(B12="?", ROUND(AVERAGEIF(B:B, "<>?"), 0), B12) -> 2001 | D12: Sep | E12: =IF(D12="?", "Sep", D12) -> Sep | F12: 12 | G12: =DATE(C12, MONTH(1&E12), F12) -> 37146 | H12: =DATEDIF(G12, DATE(2023,6,8), "Y") -> 21 | I12: 0 | J12: 687.54 | K12: tier - 3 | L12: =IF(K12="?", "tier - 1", K12) -> tier - 3 | M12: tier - 2 | N12: =IF(M12="?", "tier - 2", M12) -> tier - 2 | O12: R1013 | P12: =IF(O12="?", "Unknown", O12) -> R1013
A13: Id2324 | B13: 1999 | C13: =IF(B13="?", ROUND(AVERAGEIF(B:B, "<>?"), 0), B13) -> 1999 | D13: Dec | E13: =IF(D13="?", "Sep", D13) -> Dec | F13: 26 | G13: =DATE(C13, MONTH(1&E13), F13) -> 36520 | H13: =DATEDIF(G13, DATE(2023,6,8), "Y") -> 23 | I13: 0 | J13: 700 | K13: ? | L13: =IF(K13="?", "tier - 1", K13) -> tier - 1 | M13: tier - 3 | N13: =IF(M13="?", "tier - 2", M13) -> tier - 3 | O13: R1013 | P13: =IF(O13="?", "Unknown", O13) -> R1013
A14: Id2323 | B14: 1999 | C14: =IF(B14="?", ROUND(AVERAGEIF(B:B, "<>?"), 0), B14) -> 1999 | D14: Dec | E14: =IF(D14="?", "Sep", D14) -> Dec | F14: 14 | G14: =DATE(C14, MONTH(1&E14), F14) -> 36508 | H14: =DATEDIF(G14, DATE(2023,6,8), "Y") -> 23 | I14: 0 | J14: 722.99 | K14: tier - 3 | L14: =IF(K14="?", "tier - 1", K14) -> tier - 3 | M14: tier - 1 | N14: =IF(M14="?", "tier - 2", M14) -> tier - 1 | O14: R1013 | P14: =IF(O14="?", "Unknown", O14) -> R1013
A15: Id2322 | B15: 2002 | C15: =IF(B15="?", ROUND(AVERAGEIF(B:B, "<>?"), 0), B15) -> 2002 | D15: ? | E15: =IF(D15="?", "Sep", D15) -> Sep | F15: 19 | G15: =DATE(C15, MONTH(1&E15), F15) -> 37518 | H15: =DATEDIF(G15, DATE(2023,6,8), "Y") -> 20 | I15: 0 | J15: 750 | K15: tier - 3 | L15: =IF(K15="?", "tier - 1", K15) -> tier - 3 | M15: tier - 1 | N15: =IF(M15="?", "tier - 2", M15) -> tier - 1 | O15: R1012 | P15: =IF(O15="?", "Unknown", O15) -> R1012
A16: Id2321 | B16: 1993 | C16: =IF(B16="?", ROUND(AVERAGEIF(B:B, "<>?"), 0), B16) -> 1993 | D16: Aug | E16: =IF(D16="?", "Sep", D16) -> Aug | F16: 9 | G16: =DATE(C16, MONTH(1&E16), F16) -> 34190 | H16: =DATEDIF(G16, DATE(2023,6,8), "Y") -> 29 | I16: 0 | J16: 760 | K16: tier - 3 | L16: =IF(K16="?", "tier - 1", K16) -> tier - 3 | M16: tier - 1 | N16: =IF(M16="?", "tier - 2", M16) -> tier - 1 | O16: R1013 | P16: =IF(O16="?", "Unknown", O16) -> R1013
A17: Id2320 | B17: 1996 | C17: =IF(B17="?", ROUND(AVERAGEIF(B:B, "<>?"), 0), B17) -> 1996 | D17: Oct | E17: =IF(D17="?", "Sep", D17) -> Oct | F17: 22 | G17: =DATE(C17, MONTH(1&E17), F17) -> 35360 | H17: =DATEDIF(G17, DATE(2023,6,8), "Y") -> 26 | I17: 0 | J17: 760 | K17: tier - 3 | L17: =IF(K17="?", "tier - 1", K17) -> tier - 3 | M17: tier - 3 | N17: =IF(M17="?", "tier - 2", M17) -> tier - 3 | O17: R1013 | P17: =IF(O17="?", "Unknown", O17) -> R1013
A18: Id2319 | B18: 1993 | C18: =IF(B18="?", ROUND(AVERAGEIF(B:B, "<>?"), 0), B18) -> 1993 | D18: Jun | E18: =IF(D18="?", "Sep", D18) -> Jun | F18: 28 | G18: =DATE(C18, MONTH(1&E18), F18) -> 34148 | H18: =DATEDIF(G18, DATE(2023,6,8), "Y") -> 29 | I18: 0 | J18: 770 | K18: tier - 3 | L18: =IF(K18="?", "tier - 1", K18) -> tier - 3 | M18: tier - 3 | N18: =IF(M18="?", "tier - 2", M18) -> tier - 3 | O18: R1013 | P18: =IF(O18="?", "Unknown", O18) -> R1013
A19: Id2318 | B19: 1996 | C19: =IF(B19="?", ROUND(AVERAGEIF(B:B, "<>?"), 0), B19) -> 1996 | D19: ? | E19: =IF(D19="?", "Sep", D19) -> Sep | F19: 18 | G19: =DATE(C19, MONTH(1&E19), F19) -> 35326 | H19: =DATEDIF(G19, DATE(2023,6,8), "Y") -> 26 | I19: 0 | J19: 770.38 | K19: tier - 3 | L19: =IF(K19="?", "tier - 1", K19) -> tier - 3 | M19: ? | N19: =IF(M19="?", "tier - 2", M19) -> tier - 2 | O19: R1012 | P19: =IF(O19="?", "Unknown", O19) -> R1012
A20: Id2317 | B20: 1995 | C20: =IF(B20="?", ROUND(AVERAGEIF(B:B, "<>?"), 0), B20) -> 1995 | D20: Dec | E20: =IF(D20="?", "Sep", D20) -> Dec | F20: 7 | G20: =DATE(C20, MONTH(1&E20), F20) -> 35040 | H20: =DATEDIF(G20, DATE(2023,6,8), "Y") -> 27 | I20: 0 | J20: 773.54 | K20: tier - 3 | L20: =IF(K20="?", "tier - 1", K20) -> tier - 3 | M20: tier - 2 | N20: =IF(M20="?", "tier - 2", M20) -> tier - 2 | O20: R1013 | P20: =IF(O20="?", "Unknown", O20) -> R1013
A21: Id2316 | B21: 2004 | C21: =IF(B21="?", ROUND(AVERAGEIF(B:B, "<>?"), 0), B21) -> 2004 | D21: Oct | E21: =IF(D21="?", "Sep", D21) -> Oct | F21: 7 | G21: =DATE(C21, MONTH(1&E21), F21) -> 38267 | H21: =DATEDIF(G21, DATE(2023,6,8), "Y") -> 18 | I21: 0 | J21: 830.52 | K21: tier - 3 | L21: =IF(K21="?", "tier - 1", K21) -> tier - 3 | M21: tier - 2 | N21: =IF(M21="?", "tier - 2", M21) -> tier - 2 | O21: R1011 | P21: =IF(O21="?", "Unknown", O21) -> R1011
A22: Id2315 | B22: 2000 | C22: =IF(B22="?", ROUND(AVERAGEIF(B:B, "<>?"), 0), B22) -> 2000 | D22: Nov | E22: =IF(D22="?", "Sep", D22) -> Nov | F22: 18 | G22: =DATE(C22, MONTH(1&E22), F22) -> 36848 | H22: =DATEDIF(G22, DATE(2023,6,8), "Y") -> 22 | I22: 0 | J22: 865.41 | K22: tier - 3 | L22: =IF(K22="?", "tier - 1", K22) -> tier - 3 | M22: tier - 1 | N22: =IF(M22="?", "tier - 2", M22) -> tier - 1 | O22: R1013 | P22: =IF(O22="?", "Unknown", O22) -> R1013
... A1047: Id1290 | B1047: 1977 | C1047: =IF(B1047="?", ROUND(AVERAGEIF(B:B, "<>?"), 0), B1047) -> 1977 | D1047: Jul | E1047: =IF(D1047="?", "Sep", D1047) -> Jul | F1047: 26 | G1047: =DATE(C1047, MONTH(1&E1047), F1047) -> 28332 | H1047: =DATEDIF(G1047, DATE(2023,6,8), "Y") -> 45 | I1047: 2 | J1047: 8527.53 | K1047: tier - 2 | L1047: =IF(K1047="?", "tier - 1", K1047) -> tier - 2 | M1047: tier - 2 | N1047: =IF(M1047="?", "tier - 2", M1047) -> tier - 2 | O1047: R1013 | P1047: =IF(O1047="?", "Unknown", O1047) -> R1013
A1048: Id1289 | B1048: ? | C1048: =IF(B1048="?", ROUND(AVERAGEIF(B:B, "<>?"), 0), B1048) -> 1983 | D1048: Jul | E1048: =IF(D1048="?", "Sep", D1048) -> Jul | F1048: 24 | G1048: =DATE(C1048, MONTH(1&E1048), F1048) -> 30521 | H1048: =DATEDIF(G1048, DATE(2023,6,8), "Y") -> 39 | I1048: 0 | J1048: 8534.67 | K1048: tier - 2 | L1048: =IF(K1048="?", "tier - 1", K1048) -> tier - 2 | M1048: tier - 3 | N1048: =IF(M1048="?", "tier - 2", M1048) -> tier - 3 | O1048: R1024 | P1048: =IF(O1048="?", "Unknown", O1048) -> R1024
A1049: Id1288 | B1049: 1981 | C1049: =IF(B1049="?", ROUND(AVERAGEIF(B:B, "<>?"), 0), B1049) -> 1981 | D1049: Dec | E1049: =IF(D1049="?", "Sep", D1049) -> Dec | F1049: 27 | G1049: =DATE(C1049, MONTH(1&E1049), F1049) -> 29947 | H1049: =DATEDIF(G1049, DATE(2023,6,8), "Y") -> 41 | I1049: 3 | J1049: 8538.29 | K1049: tier - 2 | L1049: =IF(K1049="?", "tier - 1", K1049) -> tier - 2 | M1049: tier - 3 | N1049: =IF(M1049="?", "tier - 2", M1049) -> tier - 3 | O1049: R1024 | P1049: =IF(O1049="?", "Unknown", O1049) -> R1024
A1050: Id1287 | B1050: 1975 | C1050: =IF(B1050="?", ROUND(AVERAGEIF(B:B, "<>?"), 0), B1050) -> 1975 | D1050: Nov | E1050: =IF(D1050="?", "Sep", D1050) -> Nov | F1050: 6 | G1050: =DATE(C1050, MONTH(1&E1050), F1050) -> 27704 | H1050: =DATEDIF(G1050, DATE(2023,6,8), "Y") -> 47 | I1050: 1 | J1050: 8539.67 | K1050: tier - 2 | L1050: =IF(K1050="?", "tier - 1", K1050) -> tier - 2 | M1050: tier - 3 | N1050: =IF(M1050="?", "tier - 2", M1050) -> tier - 3 | O1050: R1011 | P1050: =IF(O1050="?", "Unknown", O1050) -> R1011
A1051: Id1286 | B1051: ? | C1051: =IF(B1051="?", ROUND(AVERAGEIF(B:B, "<>?"), 0), B1051) -> 1983 | D1051: Dec | E1051: =IF(D1051="?", "Sep", D1051) -> Dec | F1051: 12 | G1051: =DATE(C1051, MONTH(1&E1051), F1051) -> 30662 | H1051: =DATEDIF(G1051, DATE(2023,6,8), "Y") -> 39 | I1051: 1 | J1051: 8547.69 | K1051: tier - 2 | L1051: =IF(K1051="?", "tier - 1", K1051) -> tier - 2 | M1051: tier - 1 | N1051: =IF(M1051="?", "tier - 2", M1051) -> tier - 1 | O1051: R1013 | P1051: =IF(O1051="?", "Unknown", O1051) -> R1013
A1052: Id1285 | B1052: 1975 | C1052: =IF(B1052="?", ROUND(AVERAGEIF(B:B, "<>?"), 0), B1052) -> 1975 | D1052: Aug | E1052: =IF(D1052="?", "Sep", D1052) -> Aug | F1052: 6 | G1052: =DATE(C1052, MONTH(1&E1052), F1052) -> 27612 | H1052: =DATEDIF(G1052, DATE(2023,6,8), "Y") -> 47 | I1052: 1 | J1052: 8551.35 | K1052: tier - 2 | L1052: =IF(K1052="?", "tier - 1", K1052) -> tier - 2 | M1052: tier - 2 | N1052: =IF(M1052="?", "tier - 2", M1052) -> tier - 2 | O1052: R1011 | P1052: =IF(O1052="?", "Unknown", O1052) -> R1011
A1053: Id1284 | B1053: 1975 | C1053: =IF(B1053="?", ROUND(AVERAGEIF(B:B, "<>?"), 0), B1053) -> 1975 | D1053: Aug | E1053: =IF(D1053="?", "Sep", D1053) -> Aug | F1053: 21 | G1053: =DATE(C1053, MONTH(1&E1053), F1053) -> 27627 | H1053: =DATEDIF(G1053, DATE(2023,6,8), "Y") -> 47 | I1053: 1 | J1053: 8556.91 | K1053: tier - 2 | L1053: =IF(K1053="?", "tier - 1", K1053) -> tier - 2 | M1053: tier - 1 | N1053: =IF(M1053="?", "tier - 2", M1053) -> tier - 1 | O1053: R1011 | P1053: =IF(O1053="?", "Unknown", O1053) -> R1011
A1054: Id1283 | B1054: 1988 | C1054: =IF(B1054="?", ROUND(AVERAGEIF(B:B, "<>?"), 0), B1054) -> 1988 | D1054: Sep | E1054: =IF(D1054="?", "Sep", D1054) -> Sep | F1054: 21 | G1054: =DATE(C1054, MONTH(1&E1054), F1054) -> 32407 | H1054: =DATEDIF(G1054, DATE(2023,6,8), "Y") -> 34 | I1054: 3 | J1054: 8567.25 | K1054: tier - 2 | L1054: =IF(K1054="?", "tier - 1", K1054) -> tier - 2 | M1054: tier - 1 | N1054: =IF(M1054="?", "tier - 2", M1054) -> tier - 1 | O1054: R1012 | P1054: =IF(O1054="?", "Unknown", O1054) -> R1012
A1055: Id1282 | B1055: 1975 | C1055: =IF(B1055="?", ROUND(AVERAGEIF(B:B, "<>?"), 0), B1055) -> 1975 | D1055: Sep | E1055: =IF(D1055="?", "Sep", D1055) -> Sep | F1055: 26 | G1055: =DATE(C1055, MONTH(1&E1055), F1055) -> 27663 | H1055: =DATEDIF(G1055, DATE(2023,6,8), "Y") -> 47 | I1055: 1 | J1055: 8569.86 | K1055: tier - 2 | L1055: =IF(K1055="?", "tier - 1", K1055) -> tier - 2 | M1055: tier - 3 | N1055: =IF(M1055="?", "tier - 2", M1055) -> tier - 3 | O1055: R1013 | P1055: =IF(O1055="?", "Unknown", O1055) -> R1013
A1056: Id1281 | B1056: 1982 | C1056: =IF(B1056="?", ROUND(AVERAGEIF(B:B, "<>?"), 0), B1056) -> 1982 | D1056: Dec | E1056: =IF(D1056="?", "Sep", D1056) -> Dec | F1056: 6 | G1056: =DATE(C1056, MONTH(1&E1056), F1056) -> 30291 | H1056: =DATEDIF(G1056, DATE(2023,6,8), "Y") -> 40 | I1056: 3 | J1056: 8572.04 | K1056: tier - 2 | L1056: =IF(K1056="?", "tier - 1", K1056) -> tier - 2 | M1056: tier - 2 | N1056: =IF(M1056="?", "tier - 2", M1056) -> tier - 2 | O1056: R1021 | P1056: =IF(O1056="?", "Unknown", O1056) -> R1021
A1057: Id1280 | B1057: 1987 | C1057: =IF(B1057="?", ROUND(AVERAGEIF(B:B, "<>?"), 0), B1057) -> 1987 | D1057: Nov | E1057: =IF(D1057="?", "Sep", D1057) -> Nov | F1057: 11 | G1057: =DATE(C1057, MONTH(1&E1057), F1057) -> 32092 | H1057: =DATEDIF(G1057, DATE(2023,6,8), "Y") -> 35 | I1057: 3 | J1057: 8573.3 | K1057: tier - 2 | L1057: =IF(K1057="?", "tier - 1", K1057) -> tier - 2 | M1057: tier - 2 | N1057: =IF(M1057="?", "tier - 2", M1057) -> tier - 2 | O1057: R1021 | P1057: =IF(O1057="?", "Unknown", O1057) -> R1021
A1058: Id1279 | B1058: 1983 | C1058: =IF(B1058="?", ROUND(AVERAGEIF(B:B, "<>?"), 0), B1058) -> 1983 | D1058: Dec | E1058: =IF(D1058="?", "Sep", D1058) -> Dec | F1058: 30 | G1058: =DATE(C1058, MONTH(1&E1058), F1058) -> 30680 | H1058: =DATEDIF(G1058, DATE(2023,6,8), "Y") -> 39 | I1058: 5 | J1058: 8582.3 | K1058: tier - 2 | L1058: =IF(K1058="?", "tier - 1", K1058) -> tier - 2 | M1058: tier - 1 | N1058: =IF(M1058="?", "tier - 2", M1058) -> tier - 1 | O1058: R1013 | P1058: =IF(O1058="?", "Unknown", O1058) -> R1013
A1059: Id1278 | B1059: 1983 | C1059: =IF(B1059="?", ROUND(AVERAGEIF(B:B, "<>?"), 0), B1059) -> 1983 | D1059: Jul | E1059: =IF(D1059="?", "Sep", D1059) -> Jul | F1059: 25 | G1059: =DATE(C1059, MONTH(1&E1059), F1059) -> 30522 | H1059: =DATEDIF(G1059, DATE(2023,6,8), "Y") -> 39 | I1059: 5 | J1059: 8596.83 | K1059: tier - 2 | L1059: =IF(K1059="?", "tier - 1", K1059) -> tier - 2 | M1059: tier - 3 | N1059: =IF(M1059="?", "tier - 2", M1059) -> tier - 3 | O1059: R1013 | P1059: =IF(O1059="?", "Unknown", O1059) -> R1013
A1060: Id1277 | B1060: 1973 | C1060: =IF(B1060="?", ROUND(AVERAGEIF(B:B, "<>?"), 0), B1060) -> 1973 | D1060: Jul | E1060: =IF(D1060="?", "Sep", D1060) -> Jul | F1060: 11 | G1060: =DATE(C1060, MONTH(1&E1060), F1060) -> 26856 | H1060: =DATEDIF(G1060, DATE(2023,6,8), "Y") -> 49 | I1060: 0 | J1060: 8601.33 | K1060: tier - 2 | L1060: =IF(K1060="?", "tier - 1", K1060) -> tier - 2 | M1060: tier - 1 | N1060: =IF(M1060="?", "tier - 2", M1060) -> tier - 1 | O1060: R1013 | P1060: =IF(O1060="?", "Unknown", O1060) -> R1013
A1061: Id1276 | B1061: 1977 | C1061: =IF(B1061="?", ROUND(AVERAGEIF(B:B, "<>?"), 0), B1061) -> 1977 | D1061: Sep | E1061: =IF(D1061="?", "Sep", D1061) -> Sep | F1061: 24 | G1061: =DATE(C1061, MONTH(1&E1061), F1061) -> 28392 | H1061: =DATEDIF(G1061, DATE(2023,6,8), "Y") -> 45 | I1061: 2 | J1061: 8603.82 | K1061: tier - 2 | L1061: =IF(K1061="?", "tier - 1", K1061) -> tier - 2 | M1061: tier - 1 | N1061: =IF(M1061="?", "tier - 2", M1061) -> tier - 1 | O1061: R1019 | P1061: =IF(O1061="?", "Unknown", O1061) -> R1019
A1062: Id1275 | B1062: 1977 | C1062: =IF(B1062="?", ROUND(AVERAGEIF(B:B, "<>?"), 0), B1062) -> 1977 | D1062: Nov | E1062: =IF(D1062="?", "Sep", D1062) -> Nov | F1062: 12 | G1062: =DATE(C1062, MONTH(1&E1062), F1062) -> 28441 | H1062: =DATEDIF(G1062, DATE(2023,6,8), "Y") -> 45 | I1062: 2 | J1062: 8604.48 | K1062: tier - 3 | L1062: =IF(K1062="?", "tier - 1", K1062) -> tier - 3 | M1062: tier - 2 | N1062: =IF(M1062="?", "tier - 2", M1062) -> tier - 2 | O1062: R1016 | P1062: =IF(O1062="?", "Unknown", O1062) -> R1016
A1063: Id1274 | B1063: 1977 | C1063: =IF(B1063="?", ROUND(AVERAGEIF(B:B, "<>?"), 0), B1063) -> 1977 | D1063: Oct | E1063: =IF(D1063="?", "Sep", D1063) -> Oct | F1063: 15 | G1063: =DATE(C1063, MONTH(1&E1063), F1063) -> 28413 | H1063: =DATEDIF(G1063, DATE(2023,6,8), "Y") -> 45 | I1063: 3 | J1063: 8605.36 | K1063: tier - 2 | L1063: =IF(K1063="?", "tier - 1", K1063) -> tier - 2 | M1063: tier - 2 | N1063: =IF(M1063="?", "tier - 2", M1063) -> tier - 2 | O1063: R1013 | P1063: =IF(O1063="?", "Unknown", O1063) -> R1013
... A2338: Id1 | B2338: 1968 | C2338: =IF(B2338="?", ROUND(AVERAGEIF(B:B, "<>?"), 0), B2338) -> 1968 | D2338: Oct | E2338: =IF(D2338="?", "Sep", D2338) -> Oct | F2338: 12 | G2338: =DATE(C2338, MONTH(1&E2338), F2338) -> 25123 | H2338: =DATEDIF(G2338, DATE(2023,6,8), "Y") -> 54 | I2338: 0 | J2338: 63770.43 | K2338: tier - 1 | L2338: =IF(K2338="?", "tier - 1", K2338) -> tier - 1 | M2338: tier - 3 | N2338: =IF(M2338="?", "tier - 2", M2338) -> tier - 3 | O2338: R1013 | P2338: =IF(O2338="?", "Unknown", O2338) -> R1013

Sheet Health Care
A1: Customer ID | B1: First Name | C1: BMI | D1: HBA1C | E1: Heart Issues | F1: Any Transplants | G1: Cancer History | H1: Number of Major Surgeries | I1: Smoker | J1: Weight Status | K1: Diabetes Status | L1: Date of Birth | M1: Charges | N1: Hospital Tier | O1: City Tier | P1: State ID | Q1: Age
A2: Id1 | B2: =VLOOKUP(A2, 'Customer Names'!A:E, 4, FALSE) -> Kelly | C2: =_xlfn.XLOOKUP(A2, 'Medical Examinations'!A:A, 'Medical Examinations'!B:B, "not found") -> 47.41 | D2: =_xlfn.XLOOKUP(A2, 'Medical Examinations'!A:A, 'Medical Examinations'!D:D, "not found") -> 7.47 | E2: =_xlfn.XLOOKUP(A2, 'Medical Examinations'!A:A, 'Medical Examinations'!F:F, "not found") -> No | F2: =_xlfn.XLOOKUP(A2, 'Medical Examinations'!A:A, 'Medical Examinations'!G:G, "not found") -> No | G2: =_xlfn.XLOOKUP(A2, 'Medical Examinations'!A:A, 'Medical Examinations'!H:H, "not found") -> No | H2: =_xlfn.XLOOKUP(A2, 'Medical Examinations'!A:A, 'Medical Examinations'!J:J, "not found") -> 0 | I2: =_xlfn.XLOOKUP(A2, 'Medical Examinations'!A:A, 'Medical Examinations'!L:L, "not found") -> yes | J2: =_xlfn.XLOOKUP(A2, 'Medical Examinations'!A:A, 'Medical Examinations'!C:C, "not found") -> Obesity | K2: =_xlfn.XLOOKUP(A2, 'Medical Examinations'!A:A, 'Medical Examinations'!E:E, "not found") -> Diabetes | L2: =_xlfn.XLOOKUP(A2, 'Hospitalisation Details'!A:A, 'Hospitalisation Details'!G:G, "not found") -> 25123 | M2: =_xlfn.XLOOKUP(A2, 'Hospitalisation Details'!A:A, 'Hospitalisation Details'!J:J, "not found") -> 63770.43 | N2: =_xlfn.XLOOKUP(A2, 'Hospitalisation Details'!A:A, 'Hospitalisation Details'!L:L, "not found") -> tier - 1 | O2: =_xlfn.XLOOKUP(A2, 'Hospitalisation Details'!A:A, 'Hospitalisation Details'!N:N, "not found") -> tier - 3 | P2: =_xlfn.XLOOKUP(A2, 'Hospitalisation Details'!A:A, 'Hospitalisation Details'!P:P, "not found") -> R1013 | Q2: =_xlfn.XLOOKUP(A2, 'Hospitalisation Details'!A:A, 'Hospitalisation Details'!H:H, "not found") -> 54
A3: Id2 | B3: =VLOOKUP(A3, 'Customer Names'!A:E, 4, FALSE) -> Matthew D | C3: =_xlfn.XLOOKUP(A3, 'Medical Examinations'!A:A, 'Medical Examinations'!B:B, "not found") -> 30.36 | D3: =_xlfn.XLOOKUP(A3, 'Medical Examinations'!A:A, 'Medical Examinations'!D:D, "not found") -> 5.77 | E3: =_xlfn.XLOOKUP(A3, 'Medical Examinations'!A:A, 'Medical Examinations'!F:F, "not found") -> No | F3: =_xlfn.XLOOKUP(A3, 'Medical Examinations'!A:A, 'Medical Examinations'!G:G, "not found") -> No | G3: =_xlfn.XLOOKUP(A3, 'Medical Examinations'!A:A, 'Medical Examinations'!H:H, "not found") -> No | H3: =_xlfn.XLOOKUP(A3, 'Medical Examinations'!A:A, 'Medical Examinations'!J:J, "not found") -> 0 | I3: =_xlfn.XLOOKUP(A3, 'Medical Examinations'!A:A, 'Medical Examinations'!L:L, "not found") -> yes | J3: =_xlfn.XLOOKUP(A3, 'Medical Examinations'!A:A, 'Medical Examinations'!C:C, "not found") -> Obesity | K3: =_xlfn.XLOOKUP(A3, 'Medical Examinations'!A:A, 'Medical Examinations'!E:E, "not found") -> Prediabeties | L3: =_xlfn.XLOOKUP(A3, 'Hospitalisation Details'!A:A, 'Hospitalisation Details'!G:G, "not found") -> 28284 | M3: =_xlfn.XLOOKUP(A3, 'Hospitalisation Details'!A:A, 'Hospitalisation Details'!J:J, "not found") -> 62592.87 | N3: =_xlfn.XLOOKUP(A3, 'Hospitalisation Details'!A:A, 'Hospitalisation Details'!L:L, "not found") -> tier - 2 | O3: =_xlfn.XLOOKUP(A3, 'Hospitalisation Details'!A:A, 'Hospitalisation Details'!N:N, "not found") -> tier - 3 | P3: =_xlfn.XLOOKUP(A3, 'Hospitalisation Details'!A:A, 'Hospitalisation Details'!P:P, "not found") -> R1013 | Q3: =_xlfn.XLOOKUP(A3, 'Hospitalisation Details'!A:A, 'Hospitalisation Details'!H:H, "not found") -> 46
A4: Id3 | B4: =VLOOKUP(A4, 'Customer Names'!A:E, 4, FALSE) -> Phil | C4: =_xlfn.XLOOKUP(A4, 'Medical Examinations'!A:A, 'Medical Examinations'!B:B, "not found") -> 34.485 | D4: =_xlfn.XLOOKUP(A4, 'Medical Examinations'!A:A, 'Medical Examinations'!D:D, "not found") -> 11.87 | E4: =_xlfn.XLOOKUP(A4, 'Medical Examinations'!A:A, 'Medical Examinations'!F:F, "not found") -> yes | F4: =_xlfn.XLOOKUP(A4, 'Medical Examinations'!A:A, 'Medical Examinations'!G:G, "not found") -> No | G4: =_xlfn.XLOOKUP(A4, 'Medical Examinations'!A:A, 'Medical Examinations'!H:H, "not found") -> No | H4: =_xlfn.XLOOKUP(A4, 'Medical Examinations'!A:A, 'Medical Examinations'!J:J, "not found") -> 2 | I4: =_xlfn.XLOOKUP(A4, 'Medical Examinations'!A:A, 'Medical Examinations'!L:L, "not found") -> yes | J4: =_xlfn.XLOOKUP(A4, 'Medical Examinations'!A:A, 'Medical Examinations'!C:C, "not found") -> Obesity | K4: =_xlfn.XLOOKUP(A4, 'Medical Examinations'!A:A, 'Medical Examinations'!E:E, "not found") -> Diabetes | L4: =_xlfn.XLOOKUP(A4, 'Hospitalisation Details'!A:A, 'Hospitalisation Details'!G:G, "not found") -> 25822 | M4: =_xlfn.XLOOKUP(A4, 'Hospitalisation Details'!A:A, 'Hospitalisation Details'!J:J, "not found") -> 60021.4 | N4: =_xlfn.XLOOKUP(A4, 'Hospitalisation Details'!A:A, 'Hospitalisation Details'!L:L, "not found") -> tier - 1 | O4: =_xlfn.XLOOKUP(A4, 'Hospitalisation Details'!A:A, 'Hospitalisation Details'!N:N, "not found") -> tier - 1 | P4: =_xlfn.XLOOKUP(A4, 'Hospitalisation Details'!A:A, 'Hospitalisation Details'!P:P, "not found") -> R1012 | Q4: =_xlfn.XLOOKUP(A4, 'Hospitalisation Details'!A:A, 'Hospitalisation Details'!H:H, "not found") -> 52
A5: Id4 | B5: =VLOOKUP(A5, 'Customer Names'!A:E, 4, FALSE) -> Kelsey | C5: =_xlfn.XLOOKUP(A5, 'Medical Examinations'!A:A, 'Medical Examinations'!B:B, "not found") -> 38.095 | D5: =_xlfn.XLOOKUP(A5, 'Medical Examinations'!A:A, 'Medical Examinations'!D:D, "not found") -> 6.05 | E5: =_xlfn.XLOOKUP(A5, 'Medical Examinations'!A:A, 'Medical Examinations'!F:F, "not found") -> No | F5: =_xlfn.XLOOKUP(A5, 'Medical Examinations'!A:A, 'Medical Examinations'!G:G, "not found") -> No | G5: =_xlfn.XLOOKUP(A5, 'Medical Examinations'!A:A, 'Medical Examinations'!H:H, "not found") -> No | H5: =_xlfn.XLOOKUP(A5, 'Medical Examinations'!A:A, 'Medical Examinations'!J:J, "not found") -> 0 | I5: =_xlfn.XLOOKUP(A5, 'Medical Examinations'!A:A, 'Medical Examinations'!L:L, "not found") -> yes | J5: =_xlfn.XLOOKUP(A5, 'Medical Examinations'!A:A, 'Medical Examinations'!C:C, "not found") -> Obesity | K5: =_xlfn.XLOOKUP(A5, 'Medical Examinations'!A:A, 'Medical Examinations'!E:E, "not found") -> Prediabeties | L5: =_xlfn.XLOOKUP(A5, 'Hospitalisation Details'!A:A, 'Hospitalisation Details'!G:G, "not found") -> 33395 | M5: =_xlfn.XLOOKUP(A5, 'Hospitalisation Details'!A:A, 'Hospitalisation Details'!J:J, "not found") -> 58571.07 | N5: =_xlfn.XLOOKUP(A5, 'Hospitalisation Details'!A:A, 'Hospitalisation Details'!L:L, "not found") -> tier - 1 | O5: =_xlfn.XLOOKUP(A5, 'Hospitalisation Details'!A:A, 'Hospitalisation Details'!N:N, "not found") -> tier - 3 | P5: =_xlfn.XLOOKUP(A5, 'Hospitalisation Details'!A:A, 'Hospitalisation Details'!P:P, "not found") -> R1024 | Q5: =_xlfn.XLOOKUP(A5, 'Hospitalisation Details'!A:A, 'Hospitalisation Details'!H:H, "not found") -> 32
A6: Id5 | B6: =VLOOKUP(A6, 'Customer Names'!A:E, 4, FALSE) -> Kristyn | C6: =_xlfn.XLOOKUP(A6, 'Medical Examinations'!A:A, 'Medical Examinations'!B:B, "not found") -> 35.53 | D6: =_xlfn.XLOOKUP(A6, 'Medical Examinations'!A:A, 'Medical Examinations'!D:D, "not found") -> 5.45 | E6: =_xlfn.XLOOKUP(A6, 'Medical Examinations'!A:A, 'Medical Examinations'!F:F, "not found") -> No | F6: =_xlfn.XLOOKUP(A6, 'Medical Examinations'!A:A, 'Medical Examinations'!G:G, "not found") -> No | G6: =_xlfn.XLOOKUP(A6, 'Medical Examinations'!A:A, 'Medical Examinations'!H:H, "not found") -> No | H6: =_xlfn.XLOOKUP(A6, 'Medical Examinations'!A:A, 'Medical Examinations'!J:J, "not found") -> 0 | I6: =_xlfn.XLOOKUP(A6, 'Medical Examinations'!A:A, 'Medical Examinations'!L:L, "not found") -> yes | J6: =_xlfn.XLOOKUP(A6, 'Medical Examinations'!A:A, 'Medical Examinations'!C:C, "not found") -> Obesity | K6: =_xlfn.XLOOKUP(A6, 'Medical Examinations'!A:A, 'Medical Examinations'!E:E, "not found") -> Normal | L6: =_xlfn.XLOOKUP(A6, 'Hospitalisation Details'!A:A, 'Hospitalisation Details'!G:G, "not found") -> 32678 | M6: =_xlfn.XLOOKUP(A6, 'Hospitalisation Details'!A:A, 'Hospitalisation Details'!J:J, "not found") -> 55135.4 | N6: =_xlfn.XLOOKUP(A6, 'Hospitalisation Details'!A:A, 'Hospitalisation Details'!L:L, "not found") -> tier - 1 | O6: =_xlfn.XLOOKUP(A6, 'Hospitalisation Details'!A:A, 'Hospitalisation Details'!N:N, "not found") -> tier - 2 | P6: =_xlfn.XLOOKUP(A6, 'Hospitalisation Details'!A:A, 'Hospitalisation Details'!P:P, "not found") -> R1012 | Q6: =_xlfn.XLOOKUP(A6, 'Hospitalisation Details'!A:A, 'Hospitalisation Details'!H:H, "not found") -> 33
A7: Id6 | B7: =VLOOKUP(A7, 'Customer Names'!A:E, 4, FALSE) -> Russell B. | C7: =_xlfn.XLOOKUP(A7, 'Medical Examinations'!A:A, 'Medical Examinations'!B:B, "not found") -> 32.8 | D7: =_xlfn.XLOOKUP(A7, 'Medical Examinations'!A:A, 'Medical Examinations'!D:D, "not found") -> 6.59 | E7: =_xlfn.XLOOKUP(A7, 'Medical Examinations'!A:A, 'Medical Examinations'!F:F, "not found") -> No | F7: =_xlfn.XLOOKUP(A7, 'Medical Examinations'!A:A, 'Medical Examinations'!G:G, "not found") -> No | G7: =_xlfn.XLOOKUP(A7, 'Medical Examinations'!A:A, 'Medical Examinations'!H:H, "not found") -> No | H7: =_xlfn.XLOOKUP(A7, 'Medical Examinations'!A:A, 'Medical Examinations'!J:J, "not found") -> 0 | I7: =_xlfn.XLOOKUP(A7, 'Medical Examinations'!A:A, 'Medical Examinations'!L:L, "not found") -> yes | J7: =_xlfn.XLOOKUP(A7, 'Medical Examinations'!A:A, 'Medical Examinations'!C:C, "not found") -> Obesity | K7: =_xlfn.XLOOKUP(A7, 'Medical Examinations'!A:A, 'Medical Examinations'!E:E, "not found") -> Diabetes | L7: =_xlfn.XLOOKUP(A7, 'Hospitalisation Details'!A:A, 'Hospitalisation Details'!G:G, "not found") -> 22862 | M7: =_xlfn.XLOOKUP(A7, 'Hospitalisation Details'!A:A, 'Hospitalisation Details'!J:J, "not found") -> 52590.83 | N7: =_xlfn.XLOOKUP(A7, 'Hospitalisation Details'!A:A, 'Hospitalisation Details'!L:L, "not found") -> tier - 1 | O7: =_xlfn.XLOOKUP(A7, 'Hospitalisation Details'!A:A, 'Hospitalisation Details'!N:N, "not found") -> tier - 3 | P7: =_xlfn.XLOOKUP(A7, 'Hospitalisation Details'!A:A, 'Hospitalisation Details'!P:P, "not found") -> R1011 | Q7: =_xlfn.XLOOKUP(A7, 'Hospitalisation Details'!A:A, 'Hospitalisation Details'!H:H, "not found") -> 60
A8: Id7 | B8: =VLOOKUP(A8, 'Customer Names'!A:E, 4, FALSE) -> Scott | C8: =_xlfn.XLOOKUP(A8, 'Medical Examinations'!A:A, 'Medical Examinations'!B:B, "not found") -> 36.4 | D8: =_xlfn.XLOOKUP(A8, 'Medical Examinations'!A:A, 'Medical Examinations'!D:D, "not found") -> 6.07 | E8: =_xlfn.XLOOKUP(A8, 'Medical Examinations'!A:A, 'Medical Examinations'!F:F, "not found") -> No | F8: =_xlfn.XLOOKUP(A8, 'Medical Examinations'!A:A, 'Medical Examinations'!G:G, "not found") -> No | G8: =_xlfn.XLOOKUP(A8, 'Medical Examinations'!A:A, 'Medical Examinations'!H:H, "not found") -> No | H8: =_xlfn.XLOOKUP(A8, 'Medical Examinations'!A:A, 'Medical Examinations'!J:J, "not found") -> 0 | I8: =_xlfn.XLOOKUP(A8, 'Medical Examinations'!A:A, 'Medical Examinations'!L:L, "not found") -> yes | J8: =_xlfn.XLOOKUP(A8, 'Medical Examinations'!A:A, 'Medical Examinations'!C:C, "not found") -> Obesity | K8: =_xlfn.XLOOKUP(A8, 'Medical Examinations'!A:A, 'Medical Examinations'!E:E, "not found") -> Prediabeties | L8: =_xlfn.XLOOKUP(A8, 'Hospitalisation Details'!A:A, 'Hospitalisation Details'!G:G, "not found") -> 34634 | M8: =_xlfn.XLOOKUP(A8, 'Hospitalisation Details'!A:A, 'Hospitalisation Details'!J:J, "not found") -> 51194.56 | N8: =_xlfn.XLOOKUP(A8, 'Hospitalisation Details'!A:A, 'Hospitalisation Details'!L:L, "not found") -> tier - 1 | O8: =_xlfn.XLOOKUP(A8, 'Hospitalisation Details'!A:A, 'Hospitalisation Details'!N:N, "not found") -> tier - 3 | P8: =_xlfn.XLOOKUP(A8, 'Hospitalisation Details'!A:A, 'Hospitalisation Details'!P:P, "not found") -> R1011 | Q8: =_xlfn.XLOOKUP(A8, 'Hospitalisation Details'!A:A, 'Hospitalisation Details'!H:H, "not found") -> 28
A9: Id8 | B9: =VLOOKUP(A9, 'Customer Names'!A:E, 4, FALSE) -> Stephen | C9: =_xlfn.XLOOKUP(A9, 'Medical Examinations'!A:A, 'Medical Examinations'!B:B, "not found") -> 36.96 | D9: =_xlfn.XLOOKUP(A9, 'Medical Examinations'!A:A, 'Medical Examinations'!D:D, "not found") -> 7.93 | E9: =_xlfn.XLOOKUP(A9, 'Medical Examinations'!A:A, 'Medical Examinations'!F:F, "not found") -> No | F9: =_xlfn.XLOOKUP(A9, 'Medical Examinations'!A:A, 'Medical Examinations'!G:G, "not found") -> No | G9: =_xlfn.XLOOKUP(A9, 'Medical Examinations'!A:A, 'Medical Examinations'!H:H, "not found") -> No | H9: =_xlfn.XLOOKUP(A9, 'Medical Examinations'!A:A, 'Medical Examinations'!J:J, "not found") -> 3 | I9: =_xlfn.XLOOKUP(A9, 'Medical Examinations'!A:A, 'Medical Examinations'!L:L, "not found") -> yes | J9: =_xlfn.XLOOKUP(A9, 'Medical Examinations'!A:A, 'Medical Examinations'!C:C, "not found") -> Obesity | K9: =_xlfn.XLOOKUP(A9, 'Medical Examinations'!A:A, 'Medical Examinations'!E:E, "not found") -> Diabetes | L9: =_xlfn.XLOOKUP(A9, 'Hospitalisation Details'!A:A, 'Hospitalisation Details'!G:G, "not found") -> 21363 | M9: =_xlfn.XLOOKUP(A9, 'Hospitalisation Details'!A:A, 'Hospitalisation Details'!J:J, "not found") -> 49577.66 | N9: =_xlfn.XLOOKUP(A9, 'Hospitalisation Details'!A:A, 'Hospitalisation Details'!L:L, "not found") -> tier - 2 | O9: =_xlfn.XLOOKUP(A9, 'Hospitalisation Details'!A:A, 'Hospitalisation Details'!N:N, "not found") -> tier - 2 | P9: =_xlfn.XLOOKUP(A9, 'Hospitalisation Details'!A:A, 'Hospitalisation Details'!P:P, "not found") -> R1013 | Q9: =_xlfn.XLOOKUP(A9, 'Hospitalisation Details'!A:A, 'Hospitalisation Details'!H:H, "not found") -> 64
A10: Id9 | B10: =VLOOKUP(A10, 'Customer Names'!A:E, 4, FALSE) -> Patrick R. | C10: =_xlfn.XLOOKUP(A10, 'Medical Examinations'!A:A, 'Medical Examinations'!B:B, "not found") -> 41.14 | D10: =_xlfn.XLOOKUP(A10, 'Medical Examinations'!A:A, 'Medical Examinations'!D:D, "not found") -> 9.58 | E10: =_xlfn.XLOOKUP(A10, 'Medical Examinations'!A:A, 'Medical Examinations'!F:F, "not found") -> yes | F10: =_xlfn.XLOOKUP(A10, 'Medical Examinations'!A:A, 'Medical Examinations'!G:G, "not found") -> No | G10: =_xlfn.XLOOKUP(A10, 'Medical Examinations'!A:A, 'Medical Examinations'!H:H, "not found") -> Yes | H10: =_xlfn.XLOOKUP(A10, 'Medical Examinations'!A:A, 'Medical Examinations'!J:J, "not found") -> 1 | I10: =_xlfn.XLOOKUP(A10, 'Medical Examinations'!A:A, 'Medical Examinations'!L:L, "not found") -> yes | J10: =_xlfn.XLOOKUP(A10, 'Medical Examinations'!A:A, 'Medical Examinations'!C:C, "not found") -> Obesity | K10: =_xlfn.XLOOKUP(A10, 'Medical Examinations'!A:A, 'Medical Examinations'!E:E, "not found") -> Diabetes | L10: =_xlfn.XLOOKUP(A10, 'Hospitalisation Details'!A:A, 'Hospitalisation Details'!G:G, "not found") -> 23258 | M10: =_xlfn.XLOOKUP(A10, 'Hospitalisation Details'!A:A, 'Hospitalisation Details'!J:J, "not found") -> 48970.25 | N10: =_xlfn.XLOOKUP(A10, 'Hospitalisation Details'!A:A, 'Hospitalisation Details'!L:L, "not found") -> tier - 1 | O10: =_xlfn.XLOOKUP(A10, 'Hospitalisation Details'!A:A, 'Hospitalisation Details'!N:N, "not found") -> tier - 2 | P10: =_xlfn.XLOOKUP(A10, 'Hospitalisation Details'!A:A, 'Hospitalisation Details'!P:P, "not found") -> R1013 | Q10: =_xlfn.XLOOKUP(A10, 'Hospitalisation Details'!A:A, 'Hospitalisation Details'!H:H, "not found") -> 59
A11: Id10 | B11: =VLOOKUP(A11, 'Customer Names'!A:E, 4, FALSE) -> Brooke N. | C11: =_xlfn.XLOOKUP(A11, 'Medical Examinations'!A:A, 'Medical Examinations'!B:B, "not found") -> 38.06 | D11: =_xlfn.XLOOKUP(A11, 'Medical Examinations'!A:A, 'Medical Examinations'!D:D, "not found") -> 10.79 | E11: =_xlfn.XLOOKUP(A11, 'Medical Examinations'!A:A, 'Medical Examinations'!F:F, "not found") -> No | F11: =_xlfn.XLOOKUP(A11, 'Medical Examinations'!A:A, 'Medical Examinations'!G:G, "not found") -> No | G11: =_xlfn.XLOOKUP(A11, 'Medical Examinations'!A:A, 'Medical Examinations'!H:H, "not found") -> No | H11: =_xlfn.XLOOKUP(A11, 'Medical Examinations'!A:A, 'Medical Examinations'!J:J, "not found") -> 0 | I11: =_xlfn.XLOOKUP(A11, 'Medical Examinations'!A:A, 'Medical Examinations'!L:L, "not found") -> yes | J11: =_xlfn.XLOOKUP(A11, 'Medical Examinations'!A:A, 'Medical Examinations'!C:C, "not found") -> Obesity | K11: =_xlfn.XLOOKUP(A11, 'Medical Examinations'!A:A, 'Medical Examinations'!E:E, "not found") -> Diabetes | L11: =_xlfn.XLOOKUP(A11, 'Hospitalisation Details'!A:A, 'Hospitalisation Details'!G:G, "not found") -> 28853 | M11: =_xlfn.XLOOKUP(A11, 'Hospitalisation Details'!A:A, 'Hospitalisation Details'!J:J, "not found") -> 48885.14 | N11: =_xlfn.XLOOKUP(A11, 'Hospitalisation Details'!A:A, 'Hospitalisation Details'!L:L, "not found") -> tier - 1 | O11: =_xlfn.XLOOKUP(A11, 'Hospitalisation Details'!A:A, 'Hospitalisation Details'!N:N, "not found") -> tier - 2 | P11: =_xlfn.XLOOKUP(A11, 'Hospitalisation Details'!A:A, 'Hospitalisation Details'!P:P, "not found") -> R1013 | Q11: =_xlfn.XLOOKUP(A11, 'Hospitalisation Details'!A:A, 'Hospitalisation Details'!H:H, "not found") -> 44
A12: Id11 | B12: =VLOOKUP(A12, 'Customer Names'!A:E, 4, FALSE) -> Paola Andrea | C12: =_xlfn.XLOOKUP(A12, 'Medical Examinations'!A:A, 'Medical Examinations'!B:B, "not found") -> 37.7 | D12: =_xlfn.XLOOKUP(A12, 'Medical Examinations'!A:A, 'Medical Examinations'!D:D, "not found") -> 5.96 | E12: =_xlfn.XLOOKUP(A12, 'Medical Examinations'!A:A, 'Medical Examinations'!F:F, "not found") -> yes | F12: =_xlfn.XLOOKUP(A12, 'Medical Examinations'!A:A, 'Medical Examinations'!G:G, "not found") -> No | G12: =_xlfn.XLOOKUP(A12, 'Medical Examinations'!A:A, 'Medical Examinations'!H:H, "not found") -> No | H12: =_xlfn.XLOOKUP(A12, 'Medical Examinations'!A:A, 'Medical Examinations'!J:J, "not found") -> 2 | I12: =_xlfn.XLOOKUP(A12, 'Medical Examinations'!A:A, 'Medical Examinations'!L:L, "not found") -> yes | J12: =_xlfn.XLOOKUP(A12, 'Medical Examinations'!A:A, 'Medical Examinations'!C:C, "not found") -> Obesity | K12: =_xlfn.XLOOKUP(A12, 'Medical Examinations'!A:A, 'Medical Examinations'!E:E, "not found") -> Prediabeties | L12: =_xlfn.XLOOKUP(A12, 'Hospitalisation Details'!A:A, 'Hospitalisation Details'!G:G, "not found") -> 21753 | M12: =_xlfn.XLOOKUP(A12, 'Hospitalisation Details'!A:A, 'Hospitalisation Details'!J:J, "not found") -> 48824.45 | N12: =_xlfn.XLOOKUP(A12, 'Hospitalisation Details'!A:A, 'Hospitalisation Details'!L:L, "not found") -> tier - 2 | O12: =_xlfn.XLOOKUP(A12, 'Hospitalisation Details'!A:A, 'Hospitalisation Details'!N:N, "not found") -> tier - 1 | P12: =_xlfn.XLOOKUP(A12, 'Hospitalisation Details'!A:A, 'Hospitalisation Details'!P:P, "not found") -> R1011 | Q12: =_xlfn.XLOOKUP(A12, 'Hospitalisation Details'!A:A, 'Hospitalisation Details'!H:H, "not found") -> 63
A13: Id12 | B13: =VLOOKUP(A13, 'Customer Names'!A:E, 4, FALSE) -> David | C13: =_xlfn.XLOOKUP(A13, 'Medical Examinations'!A:A, 'Medical Examinations'!B:B, "not found") -> 42.13 | D13: =_xlfn.XLOOKUP(A13, 'Medical Examinations'!A:A, 'Medical Examinations'!D:D, "not found") -> 11.9 | E13: =_xlfn.XLOOKUP(A13, 'Medical Examinations'!A:A, 'Medical Examinations'!F:F, "not found") -> No | F13: =_xlfn.XLOOKUP(A13, 'Medical Examinations'!A:A, 'Medical Examinations'!G:G, "not found") -> No | G13: =_xlfn.XLOOKUP(A13, 'Medical Examinations'!A:A, 'Medical Examinations'!H:H, "not found") -> No | H13: =_xlfn.XLOOKUP(A13, 'Medical Examinations'!A:A, 'Medical Examinations'!J:J, "not found") -> 0 | I13: =_xlfn.XLOOKUP(A13, 'Medical Examinations'!A:A, 'Medical Examinations'!L:L, "not found") -> yes | J13: =_xlfn.XLOOKUP(A13, 'Medical Examinations'!A:A, 'Medical Examinations'!C:C, "not found") -> Obesity | K13: =_xlfn.XLOOKUP(A13, 'Medical Examinations'!A:A, 'Medical Examinations'!E:E, "not found") -> Diabetes | L13: =_xlfn.XLOOKUP(A13, 'Hospitalisation Details'!A:A, 'Hospitalisation Details'!G:G, "not found") -> 24042 | M13: =_xlfn.XLOOKUP(A13, 'Hospitalisation Details'!A:A, 'Hospitalisation Details'!J:J, "not found") -> 48675.52 | N13: =_xlfn.XLOOKUP(A13, 'Hospitalisation Details'!A:A, 'Hospitalisation Details'!L:L, "not found") -> tier - 1 | O13: =_xlfn.XLOOKUP(A13, 'Hospitalisation Details'!A:A, 'Hospitalisation Details'!N:N, "not found") -> tier - 2 | P13: =_xlfn.XLOOKUP(A13, 'Hospitalisation Details'!A:A, 'Hospitalisation Details'!P:P, "not found") -> R1013 | Q13: =_xlfn.XLOOKUP(A13, 'Hospitalisation Details'!A:A, 'Hospitalisation Details'!H:H, "not found") -> 57
... A2336: Id2335 | B2336: =VLOOKUP(A2336, 'Customer Names'!A:E, 4, FALSE) -> Aaron K | C2336: =_xlfn.XLOOKUP(A2336, 'Medical Examinations'!A:A, 'Medical Examinations'!B:B, "not found") -> 17.58 | D2336: =_xlfn.XLOOKUP(A2336, 'Medical Examinations'!A:A, 'Medical Examinations'!D:D, "not found") -> 4.51 | E2336: =_xlfn.XLOOKUP(A2336, 'Medical Examinations'!A:A, 'Medical Examinations'!F:F, "not found") -> No | F2336: =_xlfn.XLOOKUP(A2336, 'Medical Examinations'!A:A, 'Medical Examinations'!G:G, "not found") -> No | G2336: =_xlfn.XLOOKUP(A2336, 'Medical Examinations'!A:A, 'Medical Examinations'!H:H, "not found") -> No | H2336: =_xlfn.XLOOKUP(A2336, 'Medical Examinations'!A:A, 'Medical Examinations'!J:J, "not found") -> 1 | I2336: =_xlfn.XLOOKUP(A2336, 'Medical Examinations'!A:A, 'Medical Examinations'!L:L, "not found") -> No | J2336: =_xlfn.XLOOKUP(A2336, 'Medical Examinations'!A:A, 'Medical Examinations'!C:C, "not found") -> Underweight | K2336: =_xlfn.XLOOKUP(A2336, 'Medical Examinations'!A:A, 'Medical Examinations'!E:E, "not found") -> Normal | L2336: =_xlfn.XLOOKUP(A2336, 'Hospitalisation Details'!A:A, 'Hospitalisation Details'!G:G, "not found") -> 33794 | M2336: =_xlfn.XLOOKUP(A2336, 'Hospitalisation Details'!A:A, 'Hospitalisation Details'!J:J, "not found") -> 563.84 | N2336: =_xlfn.XLOOKUP(A2336, 'Hospitalisation Details'!A:A, 'Hospitalisation Details'!L:L, "not found") -> tier - 2 | O2336: =_xlfn.XLOOKUP(A2336, 'Hospitalisation Details'!A:A, 'Hospitalisation Details'!N:N, "not found") -> tier - 3 | P2336: =_xlfn.XLOOKUP(A2336, 'Hospitalisation Details'!A:A, 'Hospitalisation Details'!P:P, "not found") -> R1013 | Q2336: =_xlfn.XLOOKUP(A2336, 'Hospitalisation Details'!A:A, 'Hospitalisation Details'!H:H, "not found") -> 30

Sheet Pivot Tables
A1: Smoker | B1: yes
A3: Cancer History | B3: Total
A4: No | B4: 404
A5: Yes | B5: 84
A6: Grand Total | B6: 488
A9: Smoker | B9: No
A11: Cancer History | B11: Total
A12: No | B12: 1540
A13: Yes | B13: 307
A14: Grand Total | B14: 1847
A20: Transplant History | B20: Total Major Surgeries
A21: No | B21: 1417
A22: yes | B22: 162
A23: Grand Total | B23: 1579
A25: Transplant History | B25: Average of HBA1C
A26: No | B26: 6.6704427
A27: yes | B27: 5.1876389
A28: Grand Total | B28: 6.5789979
A34: Average of Charges | B34: Column Labels
A35: Weight Status | B35: Diabetes | C35: Normal | D35: Prediabeties | E35: Grand Total
A36: Normal Weight | B36: 12447.613 | C36: 7938.5057 | D36: 10492.131 | E36: 9851.9225
A37: Obesity | B37: 19326.759 | C37: 15188.437 | D37: 15353.902 | E37: 16656.41
A38: Overweight | B38: 14293.261 | C38: 10327.157 | D38: 9737.9402 | E38: 11437.31
A39: Underweight | B39: 7442.9649 | C39: 6911.0056 | D39: 5647.7483 | E39: 6899.3175
A40: Grand Total | B40: 16120.287 | C40: 12090.723 | D40: 12532.263 | E40: 13529.918
